using System.Net;

namespace secrets_test_dotnet_api.ErrorHandling;

public class ExceptionMiddleware
{
    private readonly RequestDelegate _next;
    private readonly ILogger _logger;

    public ExceptionMiddleware(RequestDelegate next, ILogger<ExceptionMiddleware> logger)
    {
        _logger = logger;
        _next = next;
    }

    public async Task InvokeAsync(HttpContext httpContext)
    {
        try
        {
            await _next(httpContext);
        }
        catch (Exception ex)
        {
            _logger.LogError(ex, "An unexpected error occurred.");
            await HandleExceptionAsync(httpContext, ex);
        }
    }

    private static async Task HandleExceptionAsync(HttpContext context, Exception exception)
    {
        context.Response.ContentType = "application/json";
        context.Response.StatusCode = (int)HttpStatusCode.InternalServerError;
        context.Response.Headers["TraceId"] = context.TraceIdentifier;

        var message = exception is UserException ? exception.Message : "An unexpected error occurred.";
        await context.Response.WriteAsync(new ErrorDetails(context.TraceIdentifier, message).ToString());
    }
}